Not Found: /favicon.ico
Internal Server Error: /login
Traceback (most recent call last):
  File "/home/mbhatt/.pyenv/versions/testEnv-3.8.0/lib/python3.8/site-packages/django/core/handlers/exception.py", line 55, in inner
    response = get_response(request)
  File "/home/mbhatt/.pyenv/versions/testEnv-3.8.0/lib/python3.8/site-packages/django/core/handlers/base.py", line 197, in _get_response
    response = wrapped_callback(request, *callback_args, **callback_kwargs)
  File "/home/mbhatt/.pyenv/versions/testEnv-3.8.0/lib/python3.8/site-packages/django/views/decorators/csrf.py", line 54, in wrapped_view
    return view_func(*args, **kwargs)
  File "/home/mbhatt/IshikaDirectory/Documents/test2/NewsMonitoring/myNewsApp/views.py", line 44, in login
    if Source.objects.prefetch_related(Prefetch('subscribed_user', queryset=Subscriber.objects.get(user=user.id)).exists()):
AttributeError: 'Prefetch' object has no attribute 'exists'
Not Found: /favicon.ico
Not Found: /favicon.ico
Not Found: /favicon.ico
Not Found: /favicon.ico
Not Found: /favicon.ico
Internal Server Error: /forget_password
Traceback (most recent call last):
  File "/home/mbhatt/.pyenv/versions/testEnv-3.8.0/lib/python3.8/site-packages/django/core/handlers/exception.py", line 55, in inner
    response = get_response(request)
  File "/home/mbhatt/.pyenv/versions/testEnv-3.8.0/lib/python3.8/site-packages/django/core/handlers/base.py", line 197, in _get_response
    response = wrapped_callback(request, *callback_args, **callback_kwargs)
  File "/home/mbhatt/IshikaDirectory/Documents/test2/NewsMonitoring/myNewsApp/views.py", line 61, in forget_password
    u.set_password(newPassword).save()
  File "/home/mbhatt/.pyenv/versions/3.8.0/lib/python3.8/bdb.py", line 92, in trace_dispatch
    return self.dispatch_return(frame, arg)
  File "/home/mbhatt/.pyenv/versions/3.8.0/lib/python3.8/bdb.py", line 154, in dispatch_return
    if self.quitting: raise BdbQuit
bdb.BdbQuit
Internal Server Error: /forget_password
Traceback (most recent call last):
  File "/home/mbhatt/.pyenv/versions/testEnv-3.8.0/lib/python3.8/site-packages/django/core/handlers/exception.py", line 55, in inner
    response = get_response(request)
  File "/home/mbhatt/.pyenv/versions/testEnv-3.8.0/lib/python3.8/site-packages/django/core/handlers/base.py", line 197, in _get_response
    response = wrapped_callback(request, *callback_args, **callback_kwargs)
  File "/home/mbhatt/IshikaDirectory/Documents/test2/NewsMonitoring/myNewsApp/views.py", line 60, in forget_password
    u=User.objects.get(username=username)
  File "/home/mbhatt/IshikaDirectory/Documents/test2/NewsMonitoring/myNewsApp/views.py", line 60, in forget_password
    u=User.objects.get(username=username)
  File "/home/mbhatt/.pyenv/versions/3.8.0/lib/python3.8/bdb.py", line 88, in trace_dispatch
    return self.dispatch_line(frame)
  File "/home/mbhatt/.pyenv/versions/3.8.0/lib/python3.8/bdb.py", line 112, in dispatch_line
    self.user_line(frame)
  File "/home/mbhatt/.pyenv/versions/3.8.0/lib/python3.8/pdb.py", line 260, in user_line
    self.interaction(frame, None)
  File "/home/mbhatt/.pyenv/versions/testEnv-3.8.0/lib/python3.8/site-packages/IPython/core/debugger.py", line 336, in interaction
    OldPdb.interaction(self, frame, traceback)
  File "/home/mbhatt/.pyenv/versions/3.8.0/lib/python3.8/pdb.py", line 355, in interaction
    self._cmdloop()
  File "/home/mbhatt/.pyenv/versions/3.8.0/lib/python3.8/pdb.py", line 320, in _cmdloop
    self.cmdloop()
  File "/home/mbhatt/.pyenv/versions/testEnv-3.8.0/lib/python3.8/site-packages/IPython/terminal/debugger.py", line 132, in cmdloop
    line = self.thread_executor.submit(
  File "/home/mbhatt/.pyenv/versions/3.8.0/lib/python3.8/concurrent/futures/_base.py", line 439, in result
    return self.__get_result()
  File "/home/mbhatt/.pyenv/versions/3.8.0/lib/python3.8/concurrent/futures/_base.py", line 388, in __get_result
    raise self._exception
  File "/home/mbhatt/.pyenv/versions/3.8.0/lib/python3.8/concurrent/futures/thread.py", line 57, in run
    result = self.fn(*self.args, **self.kwargs)
  File "/home/mbhatt/.pyenv/versions/testEnv-3.8.0/lib/python3.8/site-packages/prompt_toolkit/shortcuts/prompt.py", line 1034, in prompt
    return self.app.run(
  File "/home/mbhatt/.pyenv/versions/testEnv-3.8.0/lib/python3.8/site-packages/prompt_toolkit/application/application.py", line 978, in run
    return loop.run_until_complete(
  File "/home/mbhatt/.pyenv/versions/3.8.0/lib/python3.8/asyncio/base_events.py", line 608, in run_until_complete
    return future.result()
  File "/home/mbhatt/.pyenv/versions/testEnv-3.8.0/lib/python3.8/site-packages/prompt_toolkit/application/application.py", line 891, in run_async
    await self.cancel_and_wait_for_background_tasks()
  File "/home/mbhatt/.pyenv/versions/testEnv-3.8.0/lib/python3.8/site-packages/prompt_toolkit/application/application.py", line 1092, in cancel_and_wait_for_background_tasks
    await task
RuntimeError: Task <Task pending name='Task-9' coro=<Application.run_async() running at /home/mbhatt/.pyenv/versions/testEnv-3.8.0/lib/python3.8/site-packages/prompt_toolkit/application/application.py:891> cb=[_run_until_complete_cb() at /home/mbhatt/.pyenv/versions/3.8.0/lib/python3.8/asyncio/base_events.py:180]> got Future <Task pending name='Task-37' coro=<KeyProcessor._start_timeout.<locals>.wait() running at /home/mbhatt/.pyenv/versions/testEnv-3.8.0/lib/python3.8/site-packages/prompt_toolkit/key_binding/key_processor.py:397> wait_for=<Future cancelled>> attached to a different loop
Internal Server Error: /forget_password
Traceback (most recent call last):
  File "/home/mbhatt/.pyenv/versions/testEnv-3.8.0/lib/python3.8/site-packages/django/core/handlers/exception.py", line 55, in inner
    response = get_response(request)
  File "/home/mbhatt/.pyenv/versions/testEnv-3.8.0/lib/python3.8/site-packages/django/core/handlers/base.py", line 197, in _get_response
    response = wrapped_callback(request, *callback_args, **callback_kwargs)
  File "/home/mbhatt/IshikaDirectory/Documents/test2/NewsMonitoring/myNewsApp/views.py", line 60, in forget_password
    u=User.objects.get(username=username)
  File "/home/mbhatt/IshikaDirectory/Documents/test2/NewsMonitoring/myNewsApp/views.py", line 60, in forget_password
    u=User.objects.get(username=username)
  File "/home/mbhatt/.pyenv/versions/3.8.0/lib/python3.8/bdb.py", line 88, in trace_dispatch
    return self.dispatch_line(frame)
  File "/home/mbhatt/.pyenv/versions/3.8.0/lib/python3.8/bdb.py", line 113, in dispatch_line
    if self.quitting: raise BdbQuit
bdb.BdbQuit
Internal Server Error: /forget_password
Traceback (most recent call last):
  File "/home/mbhatt/.pyenv/versions/testEnv-3.8.0/lib/python3.8/site-packages/django/core/handlers/exception.py", line 55, in inner
    response = get_response(request)
  File "/home/mbhatt/.pyenv/versions/testEnv-3.8.0/lib/python3.8/site-packages/django/core/handlers/base.py", line 197, in _get_response
    response = wrapped_callback(request, *callback_args, **callback_kwargs)
  File "/home/mbhatt/IshikaDirectory/Documents/test2/NewsMonitoring/myNewsApp/views.py", line 60, in forget_password
    # import logging
  File "/home/mbhatt/IshikaDirectory/Documents/test2/NewsMonitoring/myNewsApp/views.py", line 60, in forget_password
    # import logging
  File "/home/mbhatt/.pyenv/versions/3.8.0/lib/python3.8/bdb.py", line 88, in trace_dispatch
    return self.dispatch_line(frame)
  File "/home/mbhatt/.pyenv/versions/3.8.0/lib/python3.8/bdb.py", line 112, in dispatch_line
    self.user_line(frame)
  File "/home/mbhatt/.pyenv/versions/3.8.0/lib/python3.8/pdb.py", line 260, in user_line
    self.interaction(frame, None)
  File "/home/mbhatt/.pyenv/versions/testEnv-3.8.0/lib/python3.8/site-packages/IPython/core/debugger.py", line 336, in interaction
    OldPdb.interaction(self, frame, traceback)
  File "/home/mbhatt/.pyenv/versions/3.8.0/lib/python3.8/pdb.py", line 355, in interaction
    self._cmdloop()
  File "/home/mbhatt/.pyenv/versions/3.8.0/lib/python3.8/pdb.py", line 320, in _cmdloop
    self.cmdloop()
  File "/home/mbhatt/.pyenv/versions/testEnv-3.8.0/lib/python3.8/site-packages/IPython/terminal/debugger.py", line 132, in cmdloop
    line = self.thread_executor.submit(
  File "/home/mbhatt/.pyenv/versions/3.8.0/lib/python3.8/concurrent/futures/thread.py", line 181, in submit
    raise RuntimeError('cannot schedule new futures after '
RuntimeError: cannot schedule new futures after interpreter shutdown
Internal Server Error: /forget_password
Traceback (most recent call last):
  File "/home/mbhatt/.pyenv/versions/testEnv-3.8.0/lib/python3.8/site-packages/django/core/handlers/exception.py", line 55, in inner
    response = get_response(request)
  File "/home/mbhatt/.pyenv/versions/testEnv-3.8.0/lib/python3.8/site-packages/django/core/handlers/base.py", line 197, in _get_response
    response = wrapped_callback(request, *callback_args, **callback_kwargs)
  File "/home/mbhatt/IshikaDirectory/Documents/test2/NewsMonitoring/myNewsApp/views.py", line 68, in forget_password
    User.objects.get(username=username).set_password(newPassword).save()
AttributeError: 'NoneType' object has no attribute 'save'
Internal Server Error: /addstory
Traceback (most recent call last):
  File "/home/mbhatt/.pyenv/versions/testEnv-3.8.0/lib/python3.8/site-packages/django/core/handlers/exception.py", line 55, in inner
    response = get_response(request)
  File "/home/mbhatt/.pyenv/versions/testEnv-3.8.0/lib/python3.8/site-packages/django/core/handlers/base.py", line 197, in _get_response
    response = wrapped_callback(request, *callback_args, **callback_kwargs)
  File "/home/mbhatt/IshikaDirectory/Documents/test2/NewsMonitoring/myNewsApp/views.py", line 245, in addstory
    return render(request, 'myNewsApp/addstory.html', context)
  File "/home/mbhatt/.pyenv/versions/testEnv-3.8.0/lib/python3.8/site-packages/django/shortcuts.py", line 24, in render
    content = loader.render_to_string(template_name, context, request, using=using)
  File "/home/mbhatt/.pyenv/versions/testEnv-3.8.0/lib/python3.8/site-packages/django/template/loader.py", line 62, in render_to_string
    return template.render(context, request)
  File "/home/mbhatt/.pyenv/versions/testEnv-3.8.0/lib/python3.8/site-packages/django/template/backends/django.py", line 62, in render
    return self.template.render(context)
  File "/home/mbhatt/.pyenv/versions/testEnv-3.8.0/lib/python3.8/site-packages/django/template/base.py", line 175, in render
    return self._render(context)
  File "/home/mbhatt/.pyenv/versions/testEnv-3.8.0/lib/python3.8/site-packages/django/template/base.py", line 167, in _render
    return self.nodelist.render(context)
  File "/home/mbhatt/.pyenv/versions/testEnv-3.8.0/lib/python3.8/site-packages/django/template/base.py", line 1005, in render
    return SafeString("".join([node.render_annotated(context) for node in self]))
  File "/home/mbhatt/.pyenv/versions/testEnv-3.8.0/lib/python3.8/site-packages/django/template/base.py", line 1005, in <listcomp>
    return SafeString("".join([node.render_annotated(context) for node in self]))
  File "/home/mbhatt/.pyenv/versions/testEnv-3.8.0/lib/python3.8/site-packages/django/template/base.py", line 966, in render_annotated
    return self.render(context)
  File "/home/mbhatt/.pyenv/versions/testEnv-3.8.0/lib/python3.8/site-packages/django/template/defaulttags.py", line 194, in render
    len_values = len(values)
  File "/home/mbhatt/.pyenv/versions/testEnv-3.8.0/lib/python3.8/site-packages/django/db/models/query.py", line 376, in __len__
    self._fetch_all()
  File "/home/mbhatt/.pyenv/versions/testEnv-3.8.0/lib/python3.8/site-packages/django/db/models/query.py", line 1868, in _fetch_all
    self._prefetch_related_objects()
  File "/home/mbhatt/.pyenv/versions/testEnv-3.8.0/lib/python3.8/site-packages/django/db/models/query.py", line 1257, in _prefetch_related_objects
    prefetch_related_objects(self._result_cache, *self._prefetch_related_lookups)
  File "/home/mbhatt/.pyenv/versions/testEnv-3.8.0/lib/python3.8/site-packages/django/db/models/query.py", line 2297, in prefetch_related_objects
    obj_list, additional_lookups = prefetch_one_level(
  File "/home/mbhatt/.pyenv/versions/testEnv-3.8.0/lib/python3.8/site-packages/django/db/models/query.py", line 2439, in prefetch_one_level
    ) = prefetcher.get_prefetch_queryset(instances, lookup.get_current_queryset(level))
  File "/home/mbhatt/.pyenv/versions/testEnv-3.8.0/lib/python3.8/site-packages/django/db/models/fields/related_descriptors.py", line 127, in get_prefetch_queryset
    queryset._add_hints(instance=instances[0])
AttributeError: 'Subscriber' object has no attribute '_add_hints'
Internal Server Error: /addstory
Traceback (most recent call last):
  File "/home/mbhatt/.pyenv/versions/testEnv-3.8.0/lib/python3.8/site-packages/django/core/handlers/exception.py", line 55, in inner
    response = get_response(request)
  File "/home/mbhatt/.pyenv/versions/testEnv-3.8.0/lib/python3.8/site-packages/django/core/handlers/base.py", line 197, in _get_response
    response = wrapped_callback(request, *callback_args, **callback_kwargs)
  File "/home/mbhatt/IshikaDirectory/Documents/test2/NewsMonitoring/myNewsApp/views.py", line 245, in addstory
    print(context)
  File "/home/mbhatt/.pyenv/versions/testEnv-3.8.0/lib/python3.8/site-packages/django/db/models/query.py", line 370, in __repr__
    data = list(self[: REPR_OUTPUT_SIZE + 1])
  File "/home/mbhatt/.pyenv/versions/testEnv-3.8.0/lib/python3.8/site-packages/django/db/models/query.py", line 376, in __len__
    self._fetch_all()
  File "/home/mbhatt/.pyenv/versions/testEnv-3.8.0/lib/python3.8/site-packages/django/db/models/query.py", line 1868, in _fetch_all
    self._prefetch_related_objects()
  File "/home/mbhatt/.pyenv/versions/testEnv-3.8.0/lib/python3.8/site-packages/django/db/models/query.py", line 1257, in _prefetch_related_objects
    prefetch_related_objects(self._result_cache, *self._prefetch_related_lookups)
  File "/home/mbhatt/.pyenv/versions/testEnv-3.8.0/lib/python3.8/site-packages/django/db/models/query.py", line 2297, in prefetch_related_objects
    obj_list, additional_lookups = prefetch_one_level(
  File "/home/mbhatt/.pyenv/versions/testEnv-3.8.0/lib/python3.8/site-packages/django/db/models/query.py", line 2439, in prefetch_one_level
    ) = prefetcher.get_prefetch_queryset(instances, lookup.get_current_queryset(level))
  File "/home/mbhatt/.pyenv/versions/testEnv-3.8.0/lib/python3.8/site-packages/django/db/models/fields/related_descriptors.py", line 127, in get_prefetch_queryset
    queryset._add_hints(instance=instances[0])
AttributeError: 'Subscriber' object has no attribute '_add_hints'
